{"uuid": "8eccf6ea-0d38-4dbd-a620-3f2bd705574a", "children": ["0cae40e6-0b93-4c47-9b6d-68c128eb4434"], "befores": [{"name": "session_remote_driver", "status": "passed", "start": 1590141672859, "stop": 1590141677637}], "afters": [{"name": "session_remote_driver::0", "status": "broken", "statusDetails": {"message": "selenium.common.exceptions.InvalidSessionIdException: Message: Tried to run command without establishing a connection\n\n", "trace": "  File \"C:\\Users\\luozhongwen\\AppData\\Local\\Programs\\Python\\Python38\\lib\\site-packages\\allure_commons\\_allure.py\", line 185, in __call__\n    return self._fixture_function(*args, **kwargs)\n  File \"C:\\Users\\luozhongwen\\AppData\\Local\\Programs\\Python\\Python38\\lib\\site-packages\\_pytest\\fixtures.py\", line 800, in _teardown_yield_fixture\n    next(it)\n  File \"D:\\TestScriptDir\\ui_auto_frame\\ui_auto_frame_v2\\conftest.py\", line 38, in session_remote_driver\n    driver.quit()\n  File \"C:\\Users\\luozhongwen\\AppData\\Local\\Programs\\Python\\Python38\\lib\\site-packages\\selenium\\webdriver\\remote\\webdriver.py\", line 698, in quit\n    self.execute(Command.QUIT)\n  File \"C:\\Users\\luozhongwen\\AppData\\Local\\Programs\\Python\\Python38\\lib\\site-packages\\selenium\\webdriver\\remote\\webdriver.py\", line 321, in execute\n    self.error_handler.check_response(response)\n  File \"C:\\Users\\luozhongwen\\AppData\\Local\\Programs\\Python\\Python38\\lib\\site-packages\\selenium\\webdriver\\remote\\errorhandler.py\", line 242, in check_response\n    raise exception_class(message, screen, stacktrace)\n"}, "start": 1590141683741, "stop": 1590141685091}], "start": 1590141672859, "stop": 1590141685091}